<?xml version="1.0" ?>
<!-- =================================================================================== -->
<!-- |    This document was autogenerated by xacro from /runtime/install/sanitation_vehicle_description/share/sanitation_vehicle_description/urdf/sanitation_vehicle.urdf.xacro | -->
<!-- |    EDITING THIS FILE BY HAND IS NOT RECOMMENDED                                 | -->
<!-- =================================================================================== -->
<robot name="sanitation_vehicle">
  <!-- Local primitive chassis avoids the upstream Gazebo-classic visual
       override colliding with URDF materials in Ogre2 / Gazebo Harmonic. -->
  <link name="base_footprint"/>
  <link name="base_link">
    <visual>
      <geometry>
        <box size="1.15 0.72 0.28"/>
      </geometry>
      <material name="sanitation_chassis_yellow">
        <color rgba="0.84 0.63 0.05 1.0"/>
      </material>
    </visual>
    <collision>
      <geometry>
        <box size="1.15 0.72 0.28"/>
      </geometry>
    </collision>
    <inertial>
      <mass value="80.0"/>
      <inertia ixx="3.978666666666667" ixy="0" ixz="0" iyy="9.339333333333332" iyz="0" izz="12.272666666666666"/>
    </inertial>
  </link>
  <joint name="base_to_footprint" type="fixed">
    <parent link="base_footprint"/>
    <child link="base_link"/>
    <origin rpy="0 0 0" xyz="0 0 0.16"/>
  </joint>
  <link name="front_left_wheel_link">
    <visual>
      <origin rpy="1.5707963267948966 0 0"/>
      <geometry>
        <cylinder length="0.08" radius="0.14"/>
      </geometry>
      <material name="front_left_wheel_material">
        <color rgba="0.12 0.32 0.62 1.0"/>
      </material>
    </visual>
    <collision>
      <origin rpy="1.5707963267948966 0 0"/>
      <geometry>
        <cylinder length="0.08" radius="0.14"/>
      </geometry>
    </collision>
    <inertial>
      <mass value="3.0"/>
      <inertia ixx="0.016300000000000002" ixy="0" ixz="0" iyy="0.029400000000000003" iyz="0" izz="0.016300000000000002"/>
    </inertial>
  </link>
  <joint name="front_left_wheel_joint" type="continuous">
    <axis xyz="0 1 0"/>
    <parent link="base_link"/>
    <child link="front_left_wheel_link"/>
    <origin rpy="0 0 0" xyz="0.38 0.4 -0.02"/>
  </joint>
  <gazebo reference="front_left_wheel_link">
    <mu1>1.0</mu1>
    <mu2>1.0</mu2>
  </gazebo>
  <link name="front_right_wheel_link">
    <visual>
      <origin rpy="1.5707963267948966 0 0"/>
      <geometry>
        <cylinder length="0.08" radius="0.14"/>
      </geometry>
      <material name="front_right_wheel_material">
        <color rgba="0.13 0.33 0.63 1.0"/>
      </material>
    </visual>
    <collision>
      <origin rpy="1.5707963267948966 0 0"/>
      <geometry>
        <cylinder length="0.08" radius="0.14"/>
      </geometry>
    </collision>
    <inertial>
      <mass value="3.0"/>
      <inertia ixx="0.016300000000000002" ixy="0" ixz="0" iyy="0.029400000000000003" iyz="0" izz="0.016300000000000002"/>
    </inertial>
  </link>
  <joint name="front_right_wheel_joint" type="continuous">
    <axis xyz="0 1 0"/>
    <parent link="base_link"/>
    <child link="front_right_wheel_link"/>
    <origin rpy="0 0 0" xyz="0.38 -0.4 -0.02"/>
  </joint>
  <gazebo reference="front_right_wheel_link">
    <mu1>1.0</mu1>
    <mu2>1.0</mu2>
  </gazebo>
  <link name="rear_left_wheel_link">
    <visual>
      <origin rpy="1.5707963267948966 0 0"/>
      <geometry>
        <cylinder length="0.08" radius="0.14"/>
      </geometry>
      <material name="rear_left_wheel_material">
        <color rgba="0.14 0.34 0.64 1.0"/>
      </material>
    </visual>
    <collision>
      <origin rpy="1.5707963267948966 0 0"/>
      <geometry>
        <cylinder length="0.08" radius="0.14"/>
      </geometry>
    </collision>
    <inertial>
      <mass value="3.0"/>
      <inertia ixx="0.016300000000000002" ixy="0" ixz="0" iyy="0.029400000000000003" iyz="0" izz="0.016300000000000002"/>
    </inertial>
  </link>
  <joint name="rear_left_wheel_joint" type="continuous">
    <axis xyz="0 1 0"/>
    <parent link="base_link"/>
    <child link="rear_left_wheel_link"/>
    <origin rpy="0 0 0" xyz="-0.38 0.4 -0.02"/>
  </joint>
  <gazebo reference="rear_left_wheel_link">
    <mu1>1.0</mu1>
    <mu2>1.0</mu2>
  </gazebo>
  <link name="rear_right_wheel_link">
    <visual>
      <origin rpy="1.5707963267948966 0 0"/>
      <geometry>
        <cylinder length="0.08" radius="0.14"/>
      </geometry>
      <material name="rear_right_wheel_material">
        <color rgba="0.15 0.35 0.65 1.0"/>
      </material>
    </visual>
    <collision>
      <origin rpy="1.5707963267948966 0 0"/>
      <geometry>
        <cylinder length="0.08" radius="0.14"/>
      </geometry>
    </collision>
    <inertial>
      <mass value="3.0"/>
      <inertia ixx="0.016300000000000002" ixy="0" ixz="0" iyy="0.029400000000000003" iyz="0" izz="0.016300000000000002"/>
    </inertial>
  </link>
  <joint name="rear_right_wheel_joint" type="continuous">
    <axis xyz="0 1 0"/>
    <parent link="base_link"/>
    <child link="rear_right_wheel_link"/>
    <origin rpy="0 0 0" xyz="-0.38 -0.4 -0.02"/>
  </joint>
  <gazebo reference="rear_right_wheel_link">
    <mu1>1.0</mu1>
    <mu2>1.0</mu2>
  </gazebo>
  <link name="imu_link"/>
  <joint name="imu_to_base_link" type="fixed">
    <parent link="base_link"/>
    <child link="imu_link"/>
    <origin rpy="0 0 0" xyz="0 0 0"/>
  </joint>
  <gazebo>
    <plugin filename="gz-sim-imu-system" name="gz::sim::systems::Imu">
      </plugin>
  </gazebo>
  <gazebo reference="imu_link">
    <sensor name="imu_sensor" type="imu">
      <topic>imu/data</topic>
      <update_rate>50</update_rate>
      <always_on>true</always_on>
      <visualize>true</visualize>
    </sensor>
  </gazebo>
  <link name="laser">
    <visual>
      <geometry>
        <cylinder length="0.06" radius="0.045"/>
      </geometry>
      <material name="sanitation_lidar_green">
        <color rgba="0.02 0.55 0.20 1.0"/>
      </material>
    </visual>
    <collision>
      <geometry>
        <cylinder length="0.06" radius="0.045"/>
      </geometry>
    </collision>
    <inertial>
      <mass value="0.1"/>
      <inertia ixx="0.00006" ixy="0" ixz="0" iyy="0.00006" iyz="0" izz="0.00010"/>
    </inertial>
  </link>
  <joint name="laser_to_base_link" type="fixed">
    <parent link="base_link"/>
    <child link="laser"/>
    <origin rpy="0 0 0" xyz="0.12 0 0.48"/>
  </joint>
  <gazebo reference="laser">
    <sensor name="sanitation_gpu_lidar" type="gpu_lidar">
      <topic>scan</topic>
      <update_rate>10</update_rate>
      <always_on>true</always_on>
      <visualize>true</visualize>
      <lidar>
        <scan>
          <horizontal>
            <samples>360</samples>
            <resolution>1</resolution>
            <min_angle>-3.1416</min_angle>
            <max_angle>3.1416</max_angle>
          </horizontal>
          <vertical>
            <samples>1</samples>
            <resolution>1</resolution>
            <min_angle>0.0</min_angle>
            <max_angle>0.0</max_angle>
          </vertical>
        </scan>
        <range>
          <min>0.08</min>
          <max>12.0</max>
          <resolution>0.01</resolution>
        </range>
      </lidar>
    </sensor>
  </gazebo>
  <link name="camera_link">
    <visual>
      <geometry>
        <box size="0.05 0.14 0.05"/>
      </geometry>
      <material name="sanitation_camera_red">
        <color rgba="0.45 0.05 0.05 1.0"/>
      </material>
    </visual>
    <collision>
      <geometry>
        <box size="0.05 0.14 0.05"/>
      </geometry>
    </collision>
    <inertial>
      <mass value="0.135"/>
      <inertia ixx="0.00025" ixy="0" ixz="0" iyy="0.00006" iyz="0" izz="0.00025"/>
    </inertial>
  </link>
  <joint name="camera_to_base_link" type="fixed">
    <parent link="base_link"/>
    <child link="camera_link"/>
    <origin rpy="0 0.0 0" xyz="0.53 0.0 0.22"/>
  </joint>
  <link name="camera_depth_link"/>
  <joint name="camera_depth_joint" type="fixed">
    <parent link="camera_link"/>
    <child link="camera_depth_link"/>
    <origin rpy="0 0 0" xyz="0 0 0"/>
  </joint>
  <gazebo reference="camera_link">
    <sensor name="sanitation_rgbd_camera" type="rgbd_camera">
      <topic>camera</topic>
      <update_rate>15</update_rate>
      <always_on>true</always_on>
      <visualize>true</visualize>
      <camera>
        <optical_frame_id>camera_depth_link</optical_frame_id>
        <horizontal_fov>1.50098</horizontal_fov>
        <image>
          <width>640</width>
          <height>480</height>
          <format>R8G8B8</format>
        </image>
        <clip>
          <near>0.3</near>
          <far>100</far>
        </clip>
      </camera>
    </sensor>
  </gazebo>
  <gazebo>
    <plugin filename="gz-sim-diff-drive-system" name="gz::sim::systems::DiffDrive">
      <topic>cmd_vel</topic>
      <!-- <frame_id>odom</frame_id> -->
      <child_frame_id>base_footprint</child_frame_id>
      <odom_topic>odom/unfiltered</odom_topic>
      <!-- <tf_topic>/tf</tf_topic> -->
      <left_joint>front_left_wheel_joint</left_joint>
      <right_joint>front_right_wheel_joint</right_joint>
      <left_joint>rear_left_wheel_joint</left_joint>
      <right_joint>rear_right_wheel_joint</right_joint>
      <wheel_separation>0.8</wheel_separation>
      <wheel_radius>0.14</wheel_radius>
      <odom_publish_frequency>50</odom_publish_frequency>
    </plugin>
  </gazebo>
  <gazebo>
    <plugin filename="gz-sim-joint-state-publisher-system" name="gz::sim::systems::JointStatePublisher">
      <topic>joint_states</topic>
      <update_rate>50</update_rate>
      <joint_name>front_left_wheel_joint</joint_name>
      <joint_name>front_right_wheel_joint</joint_name>
      <joint_name>rear_left_wheel_joint</joint_name>
      <joint_name>rear_right_wheel_joint</joint_name>
    </plugin>
  </gazebo>
  <!-- Model-scoped Gazebo truth. Unlike the world Pose_V bridge, this topic
       has one producer bound to this model and preserves an explicit frame
       identity all the way into ROS. It is evaluation-only and must never be
       fused into the realistic odometry / localization lane. -->
  <gazebo>
    <plugin filename="gz-sim-odometry-publisher-system" name="gz::sim::systems::OdometryPublisher">
      <odom_publish_frequency>50</odom_publish_frequency>
      <odom_topic>/ground_truth/model_odom_raw</odom_topic>
      <odom_frame>world</odom_frame>
      <robot_base_frame>sanitation_vehicle/base_footprint</robot_base_frame>
      <dimensions>2</dimensions>
    </plugin>
  </gazebo>
  <!-- 40 L bin: 0.50 * 0.40 * 0.20 = 0.040 m^3. -->
  <link name="dust_bin_link">
    <visual>
      <origin xyz="0 0 0"/>
      <geometry>
        <box size="0.50 0.40 0.20"/>
      </geometry>
      <material name="bin_green">
        <color rgba="0.12 0.42 0.22 1.0"/>
      </material>
    </visual>
    <collision>
      <origin xyz="0 0 0"/>
      <geometry>
        <box size="0.50 0.40 0.20"/>
      </geometry>
    </collision>
    <inertial>
      <mass value="8.0"/>
      <inertia ixx="0.133" ixy="0" ixz="0" iyy="0.193" iyz="0" izz="0.273"/>
    </inertial>
  </link>
  <joint name="dust_bin_joint" type="fixed">
    <parent link="base_link"/>
    <child link="dust_bin_link"/>
    <origin rpy="0 0 0" xyz="-0.18 0 0.25"/>
  </joint>
  <!-- Side brushes are fixed visual/collision placeholders in Stage 2.
       Codex should add controllable joints/cleaning semantics later. -->
  <link name="left_brush_link">
    <visual>
      <geometry>
        <cylinder length="0.03" radius="0.14"/>
      </geometry>
      <material name="left_brush_dark">
        <color rgba="0.08 0.08 0.08 1.0"/>
      </material>
    </visual>
    <collision>
      <geometry>
        <cylinder length="0.03" radius="0.14"/>
      </geometry>
    </collision>
    <inertial>
      <mass value="1.0"/>
      <inertia ixx="0.00495" ixy="0" ixz="0" iyy="0.00495" iyz="0" izz="0.0098"/>
    </inertial>
  </link>
  <joint name="left_brush_joint" type="fixed">
    <parent link="base_link"/>
    <child link="left_brush_link"/>
    <origin rpy="0 0 0" xyz="0.58 0.23 -0.14"/>
  </joint>
  <link name="right_brush_link">
    <visual>
      <geometry>
        <cylinder length="0.03" radius="0.14"/>
      </geometry>
      <material name="right_brush_dark">
        <color rgba="0.09 0.09 0.09 1.0"/>
      </material>
    </visual>
    <collision>
      <geometry>
        <cylinder length="0.03" radius="0.14"/>
      </geometry>
    </collision>
    <inertial>
      <mass value="1.0"/>
      <inertia ixx="0.00495" ixy="0" ixz="0" iyy="0.00495" iyz="0" izz="0.0098"/>
    </inertial>
  </link>
  <joint name="right_brush_joint" type="fixed">
    <parent link="base_link"/>
    <child link="right_brush_link"/>
    <origin rpy="0 0 0" xyz="0.58 -0.23 -0.14"/>
  </joint>
  <!-- Non-colliding visualization of the nominal cleaning footprint. -->
  <link name="cleaning_footprint_link">
    <visual>
      <origin xyz="0 0 0"/>
      <geometry>
        <box size="0.32 0.65 0.005"/>
      </geometry>
      <material name="cleaning_zone">
        <color rgba="0.1 0.8 0.3 0.18"/>
      </material>
    </visual>
  </link>
  <joint name="cleaning_footprint_joint" type="fixed">
    <parent link="base_link"/>
    <child link="cleaning_footprint_link"/>
    <origin rpy="0 0 0" xyz="0.55 0 -0.155"/>
  </joint>
  <!-- Mounting point reserved for a future manipulator. -->
  <link name="arm_mount_link"/>
  <joint name="arm_mount_joint" type="fixed">
    <parent link="base_link"/>
    <child link="arm_mount_link"/>
    <origin rpy="0 0 0" xyz="0.10 0 0.32"/>
  </joint>
</robot>
